Workbook

Sheet Planilha2
A1: 2024 | B1: VAGAS | C1: CURSOS | D1: MATRICULAS | E1: QUALI | I1: SENAC | J1: INSCRITOS | K1: VAGAS | L1: MATRICULAS | M1: ESTADOS | N1: QUALI
A2: BELEM | B2: 1960 | C2: 11 | D2: 241 | E2: 212 | J2: 1570 | K2: 804 | L2: 306 | M2: 13 | N2: 179
A3: SANTAREM | B3: 1440 | C3: 9
A4: VIGIA | B4: 1200
A5: BRAGANÇA | B5: 160
B14: 1560 | D14: 1131 | E14: 875

Sheet TOTAIS VAG. MAT. QUALI.
A1: RELATÓRIO GERAL VAGAS OFERTADAS 2023 a 2026
C2: TOTAL GERAL 2023 | D2: TOTAL GERAL 2024 | E2: TOTAL GERAL 2025 | F2: TOTAL GERAL 2026 | G2: TOTAL GERAL 2023 A 2026
A3: Total Geral | C3: =total!I79 -> 11990 | D3: =total!I62 -> 16148 | E3: =total!I49 -> 15390 | F3: =total!I38 -> 57237 | G3: =SUM(C3:F3) -> 100765
A5: RELATÓRIO GERAL MATRICULADOS 2023 a 2026
C6: TOTAL GERAL 2023 | D6: TOTAL GERAL 2024 | E6: TOTAL GERAL 2025 | F6: TOTAL GERAL 2026 | G6: TOTAL GERAL 2023 A 2026
A7: Total Geral | C7: =total!J79 -> 8397 | D7: =total!J62 -> 9438 | E7: =total!J49 -> 13595 | F7: =total!J38 -> 2441 | G7: =SUM(C7:F7) -> 33871
A9: RELATÓRIO GERAL QUALIFICADOS 2023 a 2026
C10: TOTAL GERAL 2023 | D10: TOTAL GERAL 2024 | E10: TOTAL GERAL 2025 | F10: TOTAL GERAL 2026 | G10: TOTAL GERAL 2023 A 2026
A11: Total Geral | C11: =total!K79 -> 3986 | D11: =total!K62 -> 5838 | E11: =total!K49 -> 6924 | F11: =total!K38 -> 1953 | G11: =SUM(C11:F11) -> 18701
A14: RELATÓRIO GERAL CURSOS OFERTADOS 2023 a 2026
C15: TOTAL GERAL 2023 | D15: TOTAL GERAL 2024 | E15: TOTAL GERAL 2025 | F15: TOTAL GERAL 2026 | G15: TOTAL GERAL 2023 A 2026
A16: Total Geral | C16: =total!H79 -> 33 | D16: =total!H62 -> 119 | E16: =total!H49 -> 202 | F16: =total!H38 -> 359 | G16: =SUM(C16:F16) -> 713

Sheet total
A1: Oferta de Cursos 2026 | AC1: Oferta de Cursos (2023 a 2026) | AJ1: Total dos anos
A2: Instituições Parceiras | B2: Ano | C2: Instrumento | D2: Nº SEI | E2: Fonte de Recurso | F2: UF | G2: Cidade Sede | H2: Cursos | I2: Vagas | J2: Matriculados | K2: Qualificados | AC2: Instituições Parceiras | AD2: Ano | AE2: Cursos | AF2: Vagas | AG2: Matriculados | AH2: Qualificados | AJ2: Ano | AK2: Cursos | AL2: Vagas | AM2: Matriculados | AN2: Qualificados | AO2: Total de Estados
A3: Secretaria Estadual de Turismo do Rio Grande do Norte (SETUR-RN) | B3: 2026 | C3: Convênio nº 970061/2024 | D3: 72031.002432/2024-84 | E3: RP6 | F3: RN | G3: Natal | H3: 4 | I3: 900 | J3: 646 | K3: 311 | AC3: Secretaria Estadual de Turismo do Rio Grande do Norte (SETUR-RN) | AD3: =B3 -> 2026 | AE3: =H3 -> 4 | AF3: =I3 -> 900 | AG3: =J3 -> 646 | AH3: =K3 -> 311 | AJ3: 2023 | AK3: =H79 -> 33 | AL3: =I79 -> 11990 | AM3: =J79 -> 8397 | AN3: =K79 -> 3986 | AO3: 26+DF
A4: Associação Brasileira da Indústria de Hotéis do Rio Grande do Norte - ABIH/RN | B4: 2026 | C4: Termo de Fomento nº 971418/2024 | D4: 72031.009417/2024-67 | E4: RP6 | F4: RN | G4: Natal | H4: 4 | I4: 400 | AC4: Associação Brasileira da Indústria de Hotéis do Rio Grande do Norte - ABIH/RN | AD4: =B4 -> 2026 | AE4: =H4 -> 4 | AF4: =I4 -> 400 | AG4: =J4 -> 0 | AH4: =K4 -> 0 | AJ4: 2024 | AK4: =H62 -> 119 | AL4: =I62 -> 16148 | AM4: =J62 -> 9438 | AN4: =K62 -> 5838 | AO4: 26+DF
A5: Associação Construir de Assistência Social | B5: 2026 | C5: Termo de Fomento nº 982185/2025 | D5: 72031.007749/2025-98 | E5: RP8 | F5: RJ | G5: Rio de Janeiro | H5: 1 | I5: 600 | AC5: Associação Construir de Assistência Social | AD5: =B5 -> 2026 | AE5: =H5 -> 1 | AF5: =I5 -> 600 | AG5: =J5 -> 0 | AH5: =K5 -> 0 | AJ5: 2025 | AK5: =H49 -> 202 | AL5: =I49 -> 15390 | AM5: =J49 -> 13595 | AN5: =K49 -> 6924 | AO5: 26+DF
A6: EMPRESA ESTADUAL DE TURISMO - AMAZONASTUR | B6: 2026 | C6: Convênio nº 981882/2025 | D6: 72031.007729/2025-17 | E6: RP8 | F6: AM | G6: Manaus | H6: 3 | I6: 400 | AC6: EMPRESA ESTADUAL DE TURISMO - AMAZONASTUR | AD6: =B6 -> 2026 | AE6: =H6 -> 3 | AF6: =I6 -> 400 | AG6: =J6 -> 0 | AH6: =K6 -> 0 | AJ6: 2026 | AK6: =H38 -> 359 | AL6: =I38 -> 57237 | AM6: =J38 -> 2441 | AN6: =K38 -> 1953 | AO6: 4
A7: Instituto Conexão | B7: 2026 | C7: Termo de Fomento nº 987800/2025 | D7: 72031.010787/2025-28 | E7: RP8 | F7: RJ | G7: Rio de Janeiro | H7: 1 | I7: 4800 | AC7: Instituto Conexão | AD7: =B7 -> 2026 | AE7: =H7 -> 1 | AF7: =I7 -> 4800 | AG7: =J7 -> 0 | AH7: =K7 -> 0
A8: Instituto Federal de Educação, Ciência e Tecnologia do Maranhão - IFMA | B8: 2026 | C8: TED nº 988799/2025 | D8: 72031.009969/2025-56 | E8: RP8 | F8: MA | G8: Maranhão | H8: 25 | I8: 15640 | AC8: Instituto Federal de Educação, Ciência e Tecnologia do Maranhão - IFMA | AD8: =B8 -> 2026 | AE8: =H8 -> 25 | AF8: =I8 -> 15640 | AG8: =J8 -> 0 | AH8: =K8 -> 0
A9: Instituto Federal de Educação, Ciência e Tecnologia Do Piauí – IFPI | B9: 2026 | C9: TED nº 987841/2025 | D9: 72031.009540/2025-69 | E9: RP8 | F9: PI | G9: Piauí | H9: 4 | I9: 3200 | J9: 1795 | K9: 1642 | AC9: Instituto Federal de Educação, Ciência e Tecnologia Do Piauí – IFPI | AD9: =B9 -> 2026 | AE9: =H9 -> 4 | AF9: =I9 -> 3200 | AG9: =J9 -> 1795 | AH9: =K9 -> 1642
A10: INSTITUTO FUTURE DE JUVENTUDE, PROMOÇÃO, TURISMO, CULTURA E DESENVOLVIMENTO SUSTENTÁVEL | B10: 2026 | C10: Termo de Fomento nº 982190/2025 | D10: 72031.007746/2025-54 | E10: RP8 | F10: CE | G10: Fortaleza | H10: 1 | I10: 300 | AC10: INSTITUTO FUTURE DE JUVENTUDE, PROMOÇÃO, TURISMO, CULTURA E DESENVOLVIMENTO SUSTENTÁVEL | AD10: =B10 -> 2026 | AE10: =H10 -> 1 | AF10: =I10 -> 300 | AG10: =J10 -> 0 | AH10: =K10 -> 0
A11: INSTITUTO RESGATE ONG ESCOLA VOLUNTARIA AGRICOLA | B11: 2026 | C11: Termo de Fomento nº 981884/2025 | D11: 72031.008882/2025-61 | E11: RP8 | F11: MA | G11: Penalva | H11: 11 | I11: 440 | AC11: INSTITUTO RESGATE ONG ESCOLA VOLUNTARIA AGRICOLA | AD11: =B11 -> 2026 | AE11: =H11 -> 11 | AF11: =I11 -> 440 | AG11: =J11 -> 0 | AH11: =K11 -> 0
A12: INSTITUTO SOCIAL DE CAPELANIA EDUCACIONAL E CULTURAL DO MARANHAO ISCEC MA | B12: 2026 | C12: Termo de Fomento nº 988537/2025 | D12: 72031.011033/2025-95 | E12: RP8 | F12: MA | G12: São Luiz | H12: 6 | I12: 180 | AC12: INSTITUTO SOCIAL DE CAPELANIA EDUCACIONAL E CULTURAL DO MARANHAO ISCEC MA | AD12: =B12 -> 2026 | AE12: =H12 -> 6 | AF12: =I12 -> 180 | AG12: =J12 -> 0 | AH12: =K12 -> 0
A13: Instituto Somar Solução Brasil | B13: 2026 | C13: Termo de Fomento nº 981981/2025 | D13: 72031.007747/2025-07 | E13: RP8 | F13: RJ | G13: Rio de Janeiro | H13: 6 | I13: 840 | AC13: Instituto Somar Solução Brasil | AD13: =B13 -> 2026 | AE13: =H13 -> 6 | AF13: =I13 -> 840 | AG13: =J13 -> 0 | AH13: =K13 -> 0
A14: SERVIÇO NACIONAL DA APRESENDIZAGEM COMERCIAL - SENAC - AR/RN | B14: 2026 | C14: Convênio nº 978164/2025 | D14: 72031.004919/2025-82 | E14: RP6 | F14: RN | G14: Natal | H14: 3 | I14: 1640 | AC14: SERVIÇO NACIONAL DA APRESENDIZAGEM COMERCIAL - SENAC - AR/RN | AD14: =B14 -> 2026 | AE14: =H14 -> 3 | AF14: =I14 -> 1640 | AG14: =J14 -> 0 | AH14: =K14 -> 0
A15: Serviço Nacional de Aprendizagem Comercial do Rio Grande do Norte (SENAC-RN) | B15: 2026 | C15: Convênio nº 970093/2024 | D15: 72031.002426/2024-27 | E15: RP6 | F15: RN | G15: Natal | H15: 2 | I15: 1640 | AC15: Serviço Nacional de Aprendizagem Comercial do Rio Grande do Norte (SENAC-RN) | AD15: =B15 -> 2026 | AE15: =H15 -> 2 | AF15: =I15 -> 1640 | AG15: =J15 -> 0 | AH15: =K15 -> 0
A16: PREFEITURA MUNICIPAL DE CANINDÉ DE SÃO FRANCISCO | B16: 2026 | C16: Convênio nº 981733/2025 | D16: 72031.007722/2025-03 | E16: RP8 | F16: SE | G16: Canindé de São Francisco | H16: 13 | I16: 275 | AC16: PREFEITURA MUNICIPAL DE CANINDÉ DE SÃO FRANCISCO | AD16: =B16 -> 2026 | AE16: =H16 -> 13 | AF16: =I16 -> 275 | AG16: =J16 -> 0 | AH16: =K16 -> 0
A17: Prefeitura Municipal de Trajano de Moraes | B17: 2026 | C17: Convênio nº 981834/2025 | D17: 72031.007737/2025-63 | E17: RP8 | F17: RJ | G17: Trajano de Moraes | H17: 23 | I17: 592 | AC17: Prefeitura Municipal de Trajano de Moraes | AD17: =B17 -> 2026 | AE17: =H17 -> 23 | AF17: =I17 -> 592 | AG17: =J17 -> 0 | AH17: =K17 -> 0
A18: SECRETARIA DE ESTADO ECONOMICO DO PIAUÍ – SDE - Teresina/PI | B18: 2026 | C18: Convênio nº 981837/2025 | D18: 72031.008918/2025-15 | E18: RP8 | F18: PI | G18: Teresina | H18: 20 | I18: 800 | AC18: SECRETARIA DE ESTADO ECONOMICO DO PIAUÍ – SDE - Teresina/PI | AD18: =B18 -> 2026 | AE18: =H18 -> 20 | AF18: =I18 -> 800 | AG18: =J18 -> 0 | AH18: =K18 -> 0
A19: SECRETARIA DE ESTADO ECONOMICO DO PIAUÍ – SDE - Parnaíba/PI | B19: 2026 | C19: Convênio nº 981838/2025 | D19: 72031.008917/2025-62 | E19: RP8 | F19: PI | G19: Teresina | H19: 20 | I19: 220 | AC19: SECRETARIA DE ESTADO ECONOMICO DO PIAUÍ – SDE - Parnaíba/PI | AD19: =B19 -> 2026 | AE19: =H19 -> 20 | AF19: =I19 -> 220 | AG19: =J19 -> 0 | AH19: =K19 -> 0
A20: SECRETARIA DE ESTADO ECONOMICO DO PIAUÍ – SDE - Luzilândia/PI | B20: 2026 | C20: Convênio nº 981840/2025 | D20: 72031.008914/2025-29 | E20: RP8 | F20: PI | G20: Teresina | H20: 20 | I20: 1620 | AC20: SECRETARIA DE ESTADO ECONOMICO DO PIAUÍ – SDE - Luzilândia/PI | AD20: =B20 -> 2026 | AE20: =H20 -> 20 | AF20: =I20 -> 1620 | AG20: =J20 -> 0 | AH20: =K20 -> 0
A21: Prefeitura Municipal de Nilópolis | B21: 2026 | C21: Convênio nº 982154/2025 | D21: 72031.007723/2025-40 | E21: RP8 | F21: RJ | G21: Nilópolis | H21: 3 | I21: 150 | AC21: Prefeitura Municipal de Nilópolis | AD21: =B21 -> 2026 | AE21: =H21 -> 3 | AF21: =I21 -> 150 | AG21: =J21 -> 0 | AH21: =K21 -> 0
... A37: INSTITUTO NACIONAL DE PARCERIAS PUBLICAS - INPP | B37: 2026 | C37: Termo de Fomento nº 988679/2025 | D37: 72031.011036/2025-29 | E37: RP8 | F37: DF | G37: Brasília | H37: 20 | I37: 3000 | AC37: INSTITUTO NACIONAL DE PARCERIAS PUBLICAS - INPP | AD37: =B37 -> 2026 | AE37: =H37 -> 20 | AF37: =I37 -> 3000 | AG37: =J37 -> 0 | AH37: =K37 -> 0
A38: Total | H38: =SUM(H3:H37) -> 359 | I38: =SUM(I3:I37) -> 57237 | J38: =SUM(J3:J37) -> 2441 | K38: =SUM(K3:K37) -> 1953 | AC38: plataforma qualifica turismo (UFMA) | AD38: =B42 -> 2025 | AE38: =H42 -> 2 | AF38: =I42 -> 1004 | AG38: =J42 -> 1004 | AH38: =K42 -> 664
AC39: Instituto Federal de Educação, Ciência e Tecnologia da Paraíba - IFPB | AD39: 2025 | AE39: =H43 -> 1 | AF39: =I43 -> 377 | AG39: =J43 -> 100 | AH39: =K43 -> 69
A40: Oferta de Cursos 2025 | AC40: Instituto Federal de Educação, Ciência e Tecnologia Sul-riograndense (IFSul) | AD40: 2025 | AE40: =H44 -> 6 | AF40: =I44 -> 6000 | AG40: =J44 -> 7403 | AH40: =K44 -> 2094
A41: Instituições Parceiras | B41: Ano | C41: Instrumento | D41: Nº SEI | E41: Fonte de Recurso | F41: UF | G41: Cidade Sede | H41: Cursos | I41: Vagas | J41: Matriculados | K41: Qualificados | AC41: Escola Nacional de Turismo (IFPA) | AD41: 2025 | AE41: =H45 -> 140 | AF41: =I45 -> 4040 | AG41: =J45 -> 3479 | AH41: =K45 -> 2737
A42: plataforma qualifica turismo (UFMA) | B42: 2025 | C42: TED nº 01/2022 | D42: 72031.002275/2021-64 | E42: RP2 | F42: MA | G42: Maranhão | H42: 2 | I42: 1004 | J42: 1004 | K42: 664 | AC42: ACT Sesc/Senac | AD42: 2025 | AE42: =H46 -> 49 | AF42: =I46 -> 3731 | AG42: =J46 -> 1371 | AH42: =K46 -> 1122
A43: Instituto Federal de Educação, Ciência e Tecnologia da Paraíba - IFPB | B43: 2025 | C43: TED nº 04/2020 | D43: 72031.011478/2020-61 | E43: 0100000000 | F43: PB | G43: Paraíba | H43: 1 | I43: 377 | J43: 100 | K43: 69 | AC43: Universisade Federal Fluminense - UFF | AD43: 2025 | AE43: =H47 -> 2 | AF43: =I47 -> 45 | AG43: =J47 -> 45 | AH43: =K47 -> 45
A44: Instituto Federal de Educação, Ciência e Tecnologia Sul-riograndense (IFSul) | B44: 2025 | C44: TED nº 07/2020 | D44: 72031.013839/2020-11 | E44: RP2 | F44: RS | G44: Rio Grande do Sul | H44: 6 | I44: 6000 | J44: 7403 | K44: 2094 | AC44: Instituto Federal de Educação, Ciência e Tecnologia do Tocantins -IFTO | AD44: 2025 | AE44: =H48 -> 2 | AF44: =I48 -> 193 | AG44: =J48 -> 193 | AH44: =K48 -> 193
A45: Escola Nacional de Turismo (IFPA) | B45: 2025 | C45: TED nº 968127/2024 | D45: 72031.001167/2024-17 | E45: RP2 | F45: PA | G45: Belém | H45: 140 | I45: 4040 | J45: 3479 | K45: 2737 | AC45: plataforma qualifica turismo (UFMA) | AD45: =B53 -> 2024 | AE45: =H53 -> 12 | AF45: =I53 -> 1917 | AG45: =J53 -> 1917 | AH45: =K53 -> 1917
A46: ACT Sesc/Senac | B46: 2025 | C46: ACT nº 04/2022 | D46: 72031.006466/2023-67 | F46: PA | G46: Belém | H46: 49 | I46: 3731 | J46: 1371 | K46: 1122 | AC46: ACT Sesc/Senac | AD46: =B54 -> 2024 | AE46: =H54 -> 47 | AF46: =I54 -> 804 | AG46: =J54 -> 307 | AH46: =K54 -> 179
A47: Universisade Federal Fluminense - UFF | B47: 2025 | C47: TED nº 01/2022 | D47: 72031.011644/2022-91 | E47: 0100000000 | F47: RJ | G47: Espírito Santo | H47: 2 | I47: 45 | J47: 45 | K47: 45 | AC47: Instituto Federal de Educação, Ciência e Tecnologia da Paraíba - IFPB | AD47: =B55 -> 2024 | AE47: =H55 -> 2 | AF47: =I55 -> 919 | AG47: =J55 -> 243 | AH47: =K55 -> 160
A48: Instituto Federal de Educação, Ciência e Tecnologia do Tocantins -IFTO | B48: 2025 | C48: TED nº 004/2019 | D48: 72031.015203/2019-62 | E48: RP2 | F48: TO | G48: Palmas | H48: 2 | I48: 193 | J48: 193 | K48: 193 | AC48: Instituto Federal de Educação, Ciência e Tecnologia Sul-riograndense (IFSul) | AD48: =B56 -> 2024 | AE48: =H56 -> 6 | AF48: =I56 -> 8000 | AG48: =J56 -> 3840 | AH48: =K56 -> 1692
A49: Total | H49: =SUM(H42:H48) -> 202 | I49: =SUM(I42:I48) -> 15390 | J49: =SUM(J42:J48) -> 13595 | K49: =SUM(K42:K48) -> 6924 | AC49: Instituto Federal de Educação, Ciência e Tecnologia do Tocantins -IFTO | AD49: =B57 -> 2024 | AE49: =H57 -> 2 | AF49: =I57 -> 528 | AG49: =J57 -> 712 | AH49: =K57 -> 409
AC50: Universidade Federal do Tocantins - UFT | AD50: =B58 -> 2024 | AE50: =H58 -> 4 | AF50: =I58 -> 400 | AG50: =J58 -> 615 | AH50: =K58 -> 146
A51: Oferta de Cursos 2024 | AC51: Universidade Federal do Fluminense - UFF | AD51: =B59 -> 2024 | AE51: =H59 -> 2 | AF51: =I59 -> 450 | AG51: =J59 -> 534 | AH51: =K59 -> 572
A52: Instituições Parceiras | B52: Ano | C52: Instrumento | D52: Nº SEI | E52: Fonte de Recurso | F52: UF | G52: Cidade Sede | H52: Cursos | I52: Vagas | J52: Matriculados | K52: Qualificados | AC52: Senac-PR | AD52: =B60 -> 2024 | AE52: =H60 -> 5 | AF52: =I60 -> 1570 | AG52: =J60 -> 771 | AH52: =K60 -> 391
A53: plataforma qualifica turismo (UFMA) | B53: 2024 | C53: TED nº 01/2022 | D53: 72031.002275/2021-64 | E53: RP2 | F53: MA | G53: Maranhão | H53: 12 | I53: 1917 | J53: 1917 | K53: 1917 | AC53: Escola Nacional de Turismo (IFPA) | AD53: =B61 -> 2024 | AE53: =H61 -> 39 | AF53: =I61 -> 1560 | AG53: =J61 -> 499 | AH53: =K61 -> 372
A54: ACT Sesc/Senac | B54: 2024 | C54: ACT nº 04/2022 | D54: 72031.006466/2023-67 | F54: PA | G54: Belém | H54: 47 | I54: 804 | J54: 307 | K54: 179 | AC54: plataforma qualifica turismo (UFMA) | AD54: =B66 -> 2023 | AE54: =H66 -> 5 | AF54: =I66 -> 1570 | AG54: =J66 -> 2172 | AH54: =K66 -> 642
A55: Instituto Federal de Educação, Ciência e Tecnologia da Paraíba - IFPB | B55: 2024 | C55: TED nº 04/2020 | D55: 72031.011478/2020-61 | E55: 0100000000 | F55: PB | G55: Paraíba | H55: 2 | I55: 919 | J55: 243 | K55: 160 | AC55: Senac/PR | AD55: =B67 -> 2023 | AE55: =H67 -> 5 | AF55: =I67 -> 4672 | AG55: =J67 -> 1965 | AH55: =K67 -> 939
...

Sheet Geral
A1: Tipo de Instituição | B1: Instituições Parceiras | C1: Ano | D1: Instrumento | E1: Nº SEI | F1: Fonte de Recurso | G1: Região | H1: UF | I1: Cidade Sede | J1: Local de Realização | K1: Cursos | L1: Vagas | M1: Matriculados | N1: Qualificados
A2: PREFEITURAS | B2: PREFEITURA MUNICIPAL DE CANINDÉ DE SÃO FRANCISCO | C2: 2026 | D2: Convênio nº 981733/2025 | E2: 72031.007722/2025-03 | F2: RP8 | G2: Nordeste | H2: SE | I2: Canindé de São Francisco | J2: Canindé de São Francisco | K2: 13 | L2: 275
A3: PREFEITURAS | B3: Prefeitura Municipal de Trajano de Moraes | C3: 2026 | D3: Convênio nº 981834/2025 | E3: 72031.007737/2025-63 | F3: RP8 | G3: Sudeste | H3: RJ | I3: Trajano de Moraes | J3: Trajano de Moraes | K3: 23 | L3: 592
A4: PREFEITURAS | B4: Prefeitura Municipal de Nilópolis | C4: 2027 | D4: Convênio nº 982154/2025 | E4: 72031.007723/2025-40 | F4: RP8 | G4: Sudeste | H4: RJ | I4: Nilópolis | J4: Nilópolis | K4: 3 | L4: 150
A5: PREFEITURAS | B5: Municipio de Porangatu | C5: 2026 | D5: Convênio nº 981938/2025 | E5: 72031.007744/2025-65 | F5: RP8 | G5: Centro Oeste | H5: GO | I5: Porangatu | J5: Porangatu | K5: 4 | L5: 250
A6: PREFEITURAS | B6: MUNICÍPIO DE CAPELA | C6: 2026 | D6: Convênio nº 981970/2025 | E6: 72031.007719/2025-81 | F6: RP8 | G6: Nordeste | H6: SE | I6: Capela | J6: Capela | K6: 1 | L6: 200
A7: PREFEITURAS | B7: Prefeitura Municipal de Tibau do Sul | C7: 2026 | D7: Convênio nº 981972/2025 | E7: 72031.007727/2025-28 | F7: RP8 | G7: Nordeste | H7: RN | I7: Tibau do Sul | J7: Tibau do Sul | K7: 9 | L7: 1280
A8: PREFEITURAS | B8: Município de Iaçu | C8: 2026 | D8: Convênio nº 982032/2025 | E8: 72031.007721/2025-51 | F8: RP8 | G8: Nordeste | H8: BA | I8: Iaçu | J8: Iaçu | K8: 21 | L8: 420
A9: PREFEITURAS | B9: PREFEITURA MUNICIPAL DE WENCESLAU GUIMARÃES/BA | C9: 2026 | D9: Convênio nº 982062/2025 | E9: 72031.007745/2025-18 | F9: RP8 | G9: Nordeste | H9: BA | I9: Wenceslau Guimarães | J9: Wenceslau Guimarães | K9: 5 | L9: 200
A10: PREFEITURAS | B10: PREFEITURA MUNICIPAL DE SOBRAL | C10: 2026 | D10: Convênio nº 982074/2025 | E10: 72031.008756/2025-15 | F10: RP8 | G10: Nordeste | H10: CE | I10: Sobral | J10: Sobral | K10: 1 | L10: 150
A11: PREFEITURAS | B11: PREFEITURA MUNICIPAL DE SOBRAL | C11: 2026 | D11: Convênio nº 982143/2025 | E11: 72031.007733/2025-85 | F11: RP8 | G11: Nordeste | H11: CE | I11: Sobral | J11: Sobral | K11: 2 | L11: 150
A12: PREFEITURAS | B12: Prefeitura Municipal De Careiro | C12: 2026 | D12: Convênio nº 982173/2025 | E12: 72031.007739/2025-52 | F12: RP8 | G12: Norte | H12: AM | I12: Careiro | J12: Careiro | K12: 5 | L12: 400
A13: PREFEITURAS | B13: PREFEITURA MUNICIPAL DE CONDE/PB | C13: 2026 | D13: Convênio nº 982177/2025 | E13: 72031.009014/2025-07 | F13: RP8 | G13: Nordeste | H13: PB | I13: Conde | J13: Conde | K13: 20 | L13: 600
... A16: PREFEITURAS | B16: MUNICIPIO DE NATAL | C16: 2027 | D16: Convênio nº 988080/2025 | E16: 72031.010978/2025-90 | F16: RP8 | G16: Nordeste | H16: RN | I16: Natal | J16: Natal | K16: 11 | L16: 2375
A17: ESTADO | B17: Secretaria Estadual de Turismo do Rio Grande do Norte SETUR-RN | C17: 2026 | D17: Convênio nº 970061/2024 | E17: 72031.002432/2024-84 | F17: RP6 | G17: Nordeste | H17: RN | I17: Natal | J17: Patu, Felipe Guerra, Currais Novos, Portalegre, Acari, Lagoa Nova | K17: 4 | L17: 820 | M17: 646 | N17: 311
A18: ESTADO | B18: EMPRESA ESTADUAL DE TURISMO - AMAZONASTUR | C18: 2026 | D18: Convênio nº 981882/2025 | E18: 72031.007729/2025-17 | F18: RP8 | G18: Norte | H18: AM | I18: Manaus | J18: Tefé, Manaus, Manaus, Manacapuru, Maués, Parintins, Humaitá, Itacoatiara, Tabatinga | K18: 3 | L18: 60
A19: ESTADO | B19: EMPRESA ESTADUAL DE TURISMO - AMAZONASTUR | C19: 2027 | D19: Convênio nº 981882/2025 | E19: 72031.007729/2025-17 | F19: RP8 | G19: Norte | H19: AM | I19: Manaus | J19: Tefé, Manaus, Manaus, Manacapuru, Maués, Parintins, Humaitá, Itacoatiara, Tabatinga | K19: 3 | L19: 340
A20: ESTADO | B20: SECRETARIA DE ESTADO ECONOMICO DO PIAUÍ – SDE - Teresina/PI | C20: 2026 | D20: Convênio nº 981837/2025 | E20: 72031.008918/2025-15 | F20: RP8 | G20: Nordeste | H20: PI | I20: Teresina | J20: Teresina | K20: 20 | L20: 800
A21: ESTADO | B21: SECRETARIA DE ESTADO ECONOMICO DO PIAUÍ – SDE - Parnaíba/PI | C21: 2026 | D21: Convênio nº 981838/2025 | E21: 72031.008917/2025-62 | F21: RP8 | G21: Nordeste | H21: PI | I21: Teresina | J21: Parnaíba | K21: 20 | L21: 220
A22: ESTADO | B22: SECRETARIA DE ESTADO ECONOMICO DO PIAUÍ – SDE - Luzilândia/PI | C22: 2026 | D22: Convênio nº 981840/2025 | E22: 72031.008914/2025-29 | F22: RP8 | G22: Nordeste | H22: PI | I22: Teresina | J22: Luzilândia | K22: 20 | L22: 1620
A23: ESTADO | B23: SECRETARIA DE ESTADO DE ASSISTENCIA SOCIAL, TRABALHO, EMPREGO E RENDA -SEASTER | C23: 2026 | D23: Convênio nº 981933/2025 | E23: 72031.007724/2025-94 | F23: RP8 | G23: Norte | H23: PA | I23: Belém | J23: Ananindeua, Benevides, Marituba, Santa Bárbara do Pará | K23: 23 | L23: 500
A24: ESTADO | B24: Secretaria de Estado de Turismo – SETUR - PA | C24: 2026 | D24: Convênio nº 982176/2025 | E24: 72031.007587/2025-98 | F24: RP8 | G24: Norte | H24: PA | I24: Belém | J24: Belém | K24: 7 | L24: 5500
A25: ESTADO | B25: ESTADO DO ACRE | C25: 2027 | D25: Convênio nº 984749/2025 | E25: 72031.009977/2025-01 | F25: RP8 | G25: Norte | H25: AC | I25: Rio Branco | J25: Rio Branco, Cruzeiro do Sul, Tarauacá, Feijó, Epitaciolândia, Xapuri | K25: 4 | L25: 325
A26: INSTITUTOS FEDERAIS | B26: Instituto Federal de Educação, Ciência e Tecnologia do Maranhão - IFMA | C26: 2026 | D26: TED nº 988799/2025 | E26: 72031.009969/2025-56 | F26: RP8 | G26: Nordeste | H26: MA | I26: Maranhão | J26: Buriti dos Lopes, Amarante, São Pedro do Piauí, Teresina, Cajueiro da Praia, Arraial, Cabaceiras do Piauí, Jardim do Mulato | K26: 25 | L26: 15640
A27: INSTITUTOS FEDERAIS | B27: Instituto Federal de Educação, Ciência e Tecnologia Do Piauí – IFPI | C27: 2026 | D27: TED nº 987841/2025 | E27: 72031.009540/2025-69 | F27: RP8 | G27: Nordeste | H27: PI | I27: Piauí | J27: Batalha, Luzilândia, Teresina, José de Freitas, Campo Maior, Piripiri, Luzilândia, Parnaíba, Luís Correia, Cajueiro da Praia, | K27: 4 | L27: 3200 | M27: 1795 | N27: 1642
A28: UNIVERSIDADES | B28: plataforma qualifica turismo (UFMA) | C28: 2025 | D28: TED nº 01/2022 | E28: 72031.002275/2021-64 | F28: RP2 | G28: Nordeste | H28: MA | I28: Maranhão | J28: Nacional | K28: 2 | L28: 1004 | M28: 1004 | N28: 664
A29: INSTITUTOS FEDERAIS | B29: Instituto Federal de Educação, Ciência e Tecnologia da Paraíba - IFPB | C29: 2025 | D29: TED nº 04/2020 | E29: 72031.011478/2020-61 | F29: 0100000000 | G29: Nordeste | H29: PB | I29: Paraíba | J29: Nordeste | K29: 1 | L29: 377 | M29: 100 | N29: 69
A30: INSTITUTOS FEDERAIS | B30: Instituto Federal de Educação, Ciência e Tecnologia Sul-riograndense (IFSul) | C30: 2025 | D30: TED nº 07/2020 | E30: 72031.013839/2020-11 | F30: RP2 | G30: Sul | H30: RS | I30: Rio Grande do Sul | J30: Nacional | K30: 6 | L30: 6000 | M30: 7403 | N30: 2094
A31: UNIVERSIDADES | B31: Escola Nacional de Turismo (IFPA) | C31: 2025 | D31: TED nº 968127/2024 | E31: 72031.001167/2024-17 | F31: RP2 | G31: Norte | H31: PA | I31: Belém | J31: Belém, Santarém, Vigia, Bragança, | K31: 140 | L31: 4040 | M31: 3479 | N31: 2737
A32: UNIVERSIDADES | B32: Universidade Federal do Fluminense - UFF | C32: 2025 | D32: TED nº 01/2022 | E32: 72031.011644/2022-91 | F32: 0100000000 | G32: Sudeste | H32: RJ | I32: Espírito Santo | J32: Sudeste | K32: 2 | L32: 45 | M32: 45 | N32: 45
A33: INSTITUTOS FEDERAIS | B33: Instituto Federal de Educação, Ciência e Tecnologia do Tocantins -IFTO | C33: 2025 | D33: TED nº 004/2019 | E33: 72031.015203/2019-62 | F33: RP2 | G33: Norte | H33: TO | I33: Palmas | J33: Nacional | K33: 2 | L33: 193 | M33: 193 | N33: 193
A34: UNIVERSIDADES | B34: plataforma qualifica turismo (UFMA) | C34: 2024 | D34: TED nº 01/2022 | E34: 72031.002275/2021-64 | F34: RP2 | G34: Nordeste | H34: MA | I34: Maranhão | J34: Nacional | K34: 12 | L34: 1917 | M34: 1917 | N34: 1917
A35: INSTITUTOS FEDERAIS | B35: Instituto Federal de Educação, Ciência e Tecnologia da Paraíba - IFPB | C35: 2024 | D35: TED nº 04/2020 | E35: 72031.011478/2020-61 | F35: 0100000000 | G35: Nordeste | H35: PB | I35: Paraíba | J35: Nordeste | K35: 2 | L35: 919 | M35: 243 | N35: 160
A36: INSTITUTOS FEDERAIS | B36: Instituto Federal de Educação, Ciência e Tecnologia Sul-riograndense (IFSul) | C36: 2024 | D36: TED nº 07/2020 | E36: 72031.013839/2020-11 | F36: RP2 | G36: Sul | H36: RS | I36: Rio Grande do Sul | J36: Nacional | K36: 6 | L36: 8000 | M36: 3840 | N36: 1692
A37: INSTITUTOS FEDERAIS | B37: Instituto Federal de Educação, Ciência e Tecnologia do Tocantins -IFTO | C37: 2024 | D37: TED nº 004/2019 | E37: 72031.015203/2019-62 | F37: RP2 | G37: Norte | H37: TO | I37: Palmas | J37: Nacional | K37: 2 | L37: 528 | M37: 712 | N37: 409
A38: UNIVERSIDADES | B38: Universidade Federal do Tocantins - UFT | C38: 2024 | D38: TED nº 02/2020 | E38: 72031.011513/2020-41 | F38: 0100000000 | G38: Norte | H38: TO | I38: Tocantins | J38: Norte e Centro-Oeste | K38: 4 | L38: 400 | M38: 615 | N38: 146
... A45: UNIVERSIDADES | B45: Universidade Federal do Fluminense - UFF | C45: 2023 | D45: TED nº 01/2022 | E45: 72031.011644/2022-91 | F45: 0100000000 | G45: Sudeste | H45: RJ | I45: Espírito Santo | J45: Sudeste | K45: 2 | L45: 380 | M45: 378 | N45: 228
A46: INSTITUTOS FEDERAIS | B46: Instituto Federal de Educação, Ciência e Tecnologia do Ceará - IFCE | C46: 2023 | D46: ACT nº 02/2020 | E46: 72031.014931/2020-91 | G46: Nordeste | H46: CE | I46: Fortaleza | J46: Nacional | K46: 1 | L46: 80 | M46: 80 | N46: 33
A47: INSTITUTOS FEDERAIS | B47: Instituto Federal de Educação, Ciência e Tecnologia Sul-riograndense (IFSul) | C47: 2023 | D47: TED nº 07/2020 | E47: 72031.013839/2020-11 | F47: RP2 | G47: Sul | H47: RS | I47: Rio Grande do Sul | J47: Nacional | K47: 6 | L47: 402 | M47: 402 | N47: 402
A48: SISTEMA S | B48: SERVIÇO NACIONAL DA APRESENDIZAGEM COMERCIAL - SENAC - AR/RN | C48: 2026 | D48: Convênio nº 978164/2025 | E48: 72031.004919/2025-82 | F48: RP6 | G48: Nordeste | H48: RN | I48: Natal | J48: Acari, Angicos, Apodi, Areia Branca, Assú, Baía Formosa, Baraúna, Brejinho, Carnaúba dos Dantas, Ceará Mirim, Cerro Corá, Currais Novos, Extremoz, Felipe Guerra, Florânia, Galinhos | K48: 3 | L48: 560
...

Sheet Tipo de Instituição
A1: Tipo de Instituição | B1: Instrumento | C1: Nº SEI | D1: Fonte de Recurso | E1: UF | F1: Cidade Sede | G1: Local de Realização | H1: Ano | I1: Cursos | J1: Vagas | K1: Matriculados | L1: Qualificados
A2: ESTADO | H2: 2027 | I2: 151 | J2: 17565 | K2: 646 | L2: 311
A3: EMPRESA ESTADUAL DE TURISMO - AMAZONASTUR | B3: Convênio nº 981882/2025 | C3: 72031.007729/2025-17 | D3: RP8 | E3: AM | F3: Manaus | G3: Tefé, Manaus, Manaus, Manacapuru, Maués, Parintins, Humaitá, Itacoatiara, Tabatinga | H3: 2027 | I3: 6 | J3: 400
A4: ESTADO DO ACRE | B4: Convênio nº 984749/2025 | C4: 72031.009977/2025-01 | D4: RP8 | E4: AC | F4: Rio Branco | G4: Rio Branco, Cruzeiro do Sul, Tarauacá, Feijó, Epitaciolândia, Xapuri | H4: 2027 | I4: 4 | J4: 325
A5: FUNDACAO WALL FERRAZ | B5: Convênio nº 981951/2025 | C5: 72031.008951/2025-37 | D5: RP8 | E5: PI | F5: Teresina | G5: Teresina | H5: 2026 | I5: 47 | J5: 7380
A6: SECRETARIA DE ESTADO DE ASSISTENCIA SOCIAL, TRABALHO, EMPREGO E RENDA -SEASTER | B6: Convênio nº 981933/2025 | C6: 72031.007724/2025-94 | D6: RP8 | E6: PA | F6: Belém | G6: Ananindeua, Benevides, Marituba, Santa Bárbara do Pará | H6: 2026 | I6: 23 | J6: 500
A7: Secretaria de Estado de Turismo – SETUR - PA | B7: Convênio nº 982176/2025 | C7: 72031.007587/2025-98 | D7: RP8 | E7: PA | F7: Belém | G7: Belém | H7: 2026 | I7: 7 | J7: 5500
A8: SECRETARIA DE ESTADO ECONOMICO DO PIAUÍ – SDE - Luzilândia/PI | B8: Convênio nº 981840/2025 | C8: 72031.008914/2025-29 | D8: RP8 | E8: PI | F8: Teresina | G8: Luzilândia | H8: 2026 | I8: 20 | J8: 1620
A9: SECRETARIA DE ESTADO ECONOMICO DO PIAUÍ – SDE - Parnaíba/PI | B9: Convênio nº 981838/2025 | C9: 72031.008917/2025-62 | D9: RP8 | E9: PI | F9: Teresina | G9: Parnaíba | H9: 2026 | I9: 20 | J9: 220
A10: SECRETARIA DE ESTADO ECONOMICO DO PIAUÍ – SDE - Teresina/PI | B10: Convênio nº 981837/2025 | C10: 72031.008918/2025-15 | D10: RP8 | E10: PI | F10: Teresina | G10: Teresina | H10: 2026 | I10: 20 | J10: 800
A11: Secretaria Estadual de Turismo do Rio Grande do Norte SETUR-RN | B11: Convênio nº 970061/2024 | C11: 72031.002432/2024-84 | D11: RP6 | E11: RN | F11: Natal | G11: Patu, Felipe Guerra, Currais Novos, Portalegre, Acari, Lagoa Nova | H11: 2026 | I11: 4 | J11: 820 | K11: 646 | L11: 311
A12: INSTITUTOS FEDERAIS | H12: 2026 | I12: 98 | J12: 38729 | K12: 16560 | L12: 7954
A13: Escola Nacional de Turismo (IFPA) | B13: TED nº 968127/2024 | C13: 72031.001167/2024-17 | D13: RP2 | E13: PA | F13: Belém | G13: Belém, Santarém, Vigia, Bragança, | H13: 2024 | I13: 39 | J13: 1560 | K13: 499 | L13: 372
A14: Instituto Federal de Educação, Ciência e Tecnologia da Paraíba - IFPB | B14: TED nº 04/2020 | C14: 72031.011478/2020-61 | D14: 0100000000 | E14: PB | F14: Paraíba | G14: Nordeste | H14: 2025 | I14: 5 | J14: 2024 | K14: 534 | L14: 348
A15: Instituto Federal de Educação, Ciência e Tecnologia do Ceará - IFCE | B15: ACT nº 02/2020 | C15: 72031.014931/2020-91 | D15: (vazio) | E15: CE | F15: Fortaleza | G15: Nacional | H15: 2023 | I15: 1 | J15: 80 | K15: 80 | L15: 33
A16: Instituto Federal de Educação, Ciência e Tecnologia do Maranhão - IFMA | B16: TED nº 988799/2025 | C16: 72031.009969/2025-56 | D16: RP8 | E16: MA | F16: Maranhão | G16: Buriti dos Lopes, Amarante, São Pedro do Piauí, Teresina, Cajueiro da Praia, Arraial, Cabaceiras do Piauí, Jardim do Mulato | H16: 2026 | I16: 25 | J16: 15640
A17: Instituto Federal de Educação, Ciência e Tecnologia Do Piauí – IFPI | B17: TED nº 987841/2025 | C17: 72031.009540/2025-69 | D17: RP8 | E17: PI | F17: Piauí | G17: Batalha, Luzilândia, Teresina, José de Freitas, Campo Maior, Piripiri, Luzilândia, Parnaíba, Luís Correia, Cajueiro da Praia, | H17: 2026 | I17: 4 | J17: 3200 | K17: 1795 | L17: 1642
A18: Instituto Federal de Educação, Ciência e Tecnologia do Tocantins -IFTO | B18: TED nº 004/2019 | C18: 72031.015203/2019-62 | D18: RP2 | E18: TO | F18: Palmas | G18: Nacional | H18: 2025 | I18: 6 | J18: 1823 | K18: 2007 | L18: 1371
A19: Instituto Federal de Educação, Ciência e Tecnologia Sul-riograndense (IFSul) | B19: TED nº 07/2020 | C19: 72031.013839/2020-11 | D19: RP2 | E19: RS | F19: Rio Grande do Sul | G19: Nacional | H19: 2025 | I19: 18 | J19: 14402 | K19: 11645 | L19: 4188
A20: ORGANIZAÇÕES PARCEIRAS, ONGs | H20: 2027 | I20: 54 | J20: 10754 | K20: 108 | L20: 108
A21: Associação Brasileira da Indústria de Hotéis do Rio Grande do Norte - ABIH/RN | B21: Termo de Fomento nº 971418/2024 | C21: 72031.009417/2024-67 | D21: RP6 | E21: RN | F21: Natal | G21: Maxarangape, Serra de São Bento, Monte das Gameleiras, São Miguel do Gostoso, Baia Formosa, Tibau do Sul, Natal | H21: 2026 | I21: 4 | J21: 400
A22: Associação Construir de Assistência Social | B22: Termo de Fomento nº 982185/2025 | C22: 72031.007749/2025-98 | D22: RP8 | E22: RJ | F22: Rio de Janeiro | G22: Búzios, Guapimirim | H22: 2026 | I22: 1 | J22: 600
A23: AT do Brasil | B23: ACT nº 05/2022 | C23: 72031.013373/2022-16 | D23: (vazio) | E23: MG | F23: São Domingos do Prata | G23: Nacional | H23: 2023 | I23: 1 | J23: 100 | K23: 14 | L23: 14
A24: Incluir Treinamentos | B24: ACT nº 02/2021 | C24: 72031.012292/2021-18 | D24: (vazio) | E24: SP | F24: São Paulo | G24: Nacional | H24: 2023 | I24: 2 | J24: 94 | K24: 94 | L24: 94
A25: Instituto Conexão | B25: Termo de Fomento nº 987800/2025 | C25: 72031.010787/2025-28 | D25: RP8 | E25: RJ | F25: Rio de Janeiro | G25: Cabo Frio, Búzios, Paty do Alferes, Penedo, Petrópolis, Teresópolis, Paraty, Areal, Angra dos Reis | H25: 2027 | I25: 2 | J25: 4800
A26: INSTITUTO FUTURE DE JUVENTUDE, PROMOÇÃO, TURISMO, CULTURA E DESENVOLVIMENTO SUSTENTÁVEL | B26: Termo de Fomento nº 982190/2025 | C26: 72031.007746/2025-54 | D26: RP8 | E26: CE | F26: Fortaleza | G26: Fortaleza | H26: 2026 | I26: 1 | J26: 300
A27: INSTITUTO NACIONAL DE PARCERIAS PUBLICAS - INPP | B27: Termo de Fomento nº 988679/2025 | C27: 72031.011036/2025-29 | D27: RP8 | E27: DF | F27: Brasília | G27: Brasília | H27: 2026 | I27: 20 | J27: 3000
A28: INSTITUTO RESGATE ONG ESCOLA VOLUNTARIA AGRICOLA | B28: Termo de Fomento nº 981884/2025 | C28: 72031.008882/2025-61 | D28: RP8 | E28: MA | F28: Penalva | G28: São José de Ribamar, Paço do Lumiar, Bacuri, São Luís | H28: 2026 | I28: 11 | J28: 440
A29: INSTITUTO SOCIAL DE CAPELANIA EDUCACIONAL E CULTURAL DO MARANHAO ISCEC MA | B29: Termo de Fomento nº 988537/2025 | C29: 72031.011033/2025-95 | D29: RP8 | E29: MA | F29: São Luiz | G29: São Luís | H29: 2026 | I29: 6 | J29: 180
A30: Instituto Somar Solução Brasil | B30: Termo de Fomento nº 981981/2025 | C30: 72031.007747/2025-07 | D30: RP8 | E30: RJ | F30: Rio de Janeiro | G30: Benfica | H30: 2026 | I30: 6 | J30: 840
A31: PREFEITURAS | H31: 2027 | I31: 126 | J31: 10767
A32: MUNICÍPIO DE CAPELA | B32: Convênio nº 981970/2025 | C32: 72031.007719/2025-81 | D32: RP8 | E32: SE | F32: Capela | G32: Capela | H32: 2026 | I32: 1 | J32: 200
A33: Município de Iaçu | B33: Convênio nº 982032/2025 | C33: 72031.007721/2025-51 | D33: RP8 | E33: BA | F33: Iaçu | G33: Iaçu | H33: 2026 | I33: 21 | J33: 420
A34: MUNICIPIO DE NATAL | B34: Convênio nº 988080/2025 | C34: 72031.010978/2025-90 | D34: RP8 | E34: RN | F34: Natal | G34: Natal | H34: 2027 | I34: 15 | J34: 2500
A35: Municipio de Porangatu | B35: Convênio nº 981938/2025 | C35: 72031.007744/2025-65 | D35: RP8 | E35: GO | F35: Porangatu | G35: Porangatu | H35: 2026 | I35: 4 | J35: 250
A36: PREFEITURA MUNICIPAL DE CANINDÉ DE SÃO FRANCISCO | B36: Convênio nº 981733/2025 | C36: 72031.007722/2025-03 | D36: RP8 | E36: SE | F36: Canindé de São Francisco | G36: Canindé de São Francisco | H36: 2026 | I36: 13 | J36: 275
A37: Prefeitura Municipal De Careiro | B37: Convênio nº 982173/2025 | C37: 72031.007739/2025-52 | D37: RP8 | E37: AM | F37: Careiro | G37: Careiro | H37: 2026 | I37: 5 | J37: 400
A38: PREFEITURA MUNICIPAL DE CONDE/PB | B38: Convênio nº 982177/2025 | C38: 72031.009014/2025-07 | D38: RP8 | E38: PB | F38: Conde | G38: Conde | H38: 2026 | I38: 20 | J38: 600
A39: Prefeitura Municipal de Italva | B39: Convênio nº 982182/2025 | C39: 72031.009016/2025-98 | D39: RP8 | E39: RJ | F39: Italva | G39: Italva | H39: 2027 | I39: 4 | J39: 3600
A40: Prefeitura Municipal de Nilópolis | B40: Convênio nº 982154/2025 | C40: 72031.007723/2025-40 | D40: RP8 | E40: RJ | F40: Nilópolis | G40: Nilópolis | H40: 2027 | I40: 3 | J40: 150
...

Sheet Total Por Tipo de Instituição
A1: Instituições Parceiras | B1: Ano | C1: Instrumento | D1: Nº SEI | E1: Fonte de Recurso | F1: UF | G1: Cidade Sede | H1: Local de Realização | I1: Cursos | J1: Vagas | K1: Matriculados | L1: Qualificados
A2: PREFEITURAS E MUNICÍPIOS
A3: PREFEITURA MUNICIPAL DE CANINDÉ DE SÃO FRANCISCO | B3: 2026 | C3: Convênio nº 981733/2025 | D3: 72031.007722/2025-03 | E3: RP8 | F3: SE | G3: Canindé de São Francisco | H3: Canindé de São Francisco | I3: 13 | J3: 275
A4: Prefeitura Municipal de Trajano de Moraes | B4: 2026 | C4: Convênio nº 981834/2025 | D4: 72031.007737/2025-63 | E4: RP8 | F4: RJ | G4: Trajano de Moraes | H4: Trajano de Moraes | I4: 23 | J4: 592
A5: Prefeitura Municipal de Nilópolis | B5: 2026 | C5: Convênio nº 982154/2025 | D5: 72031.007723/2025-40 | E5: RP8 | F5: RJ | G5: Nilópolis | H5: Nilópolis | I5: 3 | J5: 150
A6: Municipio de Porangatu | B6: 2026 | C6: Convênio nº 981938/2025 | D6: 72031.007744/2025-65 | E6: RP8 | F6: GO | G6: Porangatu | H6: Porangatu | I6: 4 | J6: 250
A7: MUNICÍPIO DE CAPELA | B7: 2026 | C7: Convênio nº 981970/2025 | D7: 72031.007719/2025-81 | E7: RP8 | F7: SE | G7: Capela | H7: Capela | I7: 1 | J7: 200
A8: Prefeitura Municipal de Tibau do Sul | B8: 2026 | C8: Convênio nº 981972/2025 | D8: 72031.007727/2025-28 | E8: RP8 | F8: RN | G8: Tibau do Sul | H8: Tibau do Sul | I8: 9 | J8: 1280
A9: Município de Iaçu | B9: 2026 | C9: Convênio nº 982032/2025 | D9: 72031.007721/2025-51 | E9: RP8 | F9: BA | G9: Iaçu | H9: Iaçu | I9: 21 | J9: 420
A10: PREFEITURA MUNICIPAL DE WENCESLAU GUIMARÃES/BA | B10: 2026 | C10: Convênio nº 982062/2025 | D10: 72031.007745/2025-18 | E10: RP8 | F10: BA | G10: Wenceslau Guimarães | H10: Wenceslau Guimarães | I10: 5 | J10: 200
A11: PREFEITURA MUNICIPAL DE SOBRAL | B11: 2026 | C11: Convênio nº 982074/2025 | D11: 72031.008756/2025-15 | E11: RP8 | F11: CE | G11: Sobral | H11: Sobral | I11: 1 | J11: 150
A12: PREFEITURA MUNICIPAL DE SOBRAL | B12: 2026 | C12: Convênio nº 982143/2025 | D12: 72031.007733/2025-85 | E12: RP8 | F12: CE | G12: Sobral | H12: Sobral | I12: 2 | J12: 150
A13: Prefeitura Municipal De Careiro | B13: 2026 | C13: Convênio nº 982173/2025 | D13: 72031.007739/2025-52 | E13: RP8 | F13: AM | G13: Careiro | H13: Careiro | I13: 5 | J13: 400
A14: PREFEITURA MUNICIPAL DE CONDE/PB | B14: 2026 | C14: Convênio nº 982177/2025 | D14: 72031.009014/2025-07 | E14: RP8 | F14: PB | G14: Conde | H14: Conde | I14: 20 | J14: 600
... A16: Prefeitura de Natal | B16: 2026 | C16: Convênio nº 988080/2025 | D16: 72031.010978/2025-90 | E16: RP8 | F16: RN | G16: Natal | H16: Natal | I16: 9 | J16: 2500
A17: SubTotal | I17: =SUM(I3:I16) -> 120 | J17: =SUM(J3:J16) -> 10767 | K17: =SUM(K3:K16) -> 0 | L17: =SUM(L3:L16) -> 0
A18: SECRETARIAS E GOVERNOS ESTADUAIS
A19: Secretaria Estadual de Turismo do Rio Grande do Norte (SETUR-RN) | B19: 2026 | C19: Convênio nº 970061/2024 | D19: 72031.002432/2024-84 | E19: RP6 | F19: RN | G19: Natal | H19: Patu, Felipe Guerra, Currais Novos, Portalegre, Acari, Lagoa Nova | I19: 4 | J19: 900 | K19: 646 | L19: 311
A20: EMPRESA ESTADUAL DE TURISMO - AMAZONASTUR | B20: 2026 | C20: Convênio nº 981882/2025 | D20: 72031.007729/2025-17 | E20: RP8 | F20: AM | G20: Manaus | H20: Tefé, Manaus, Manaus, Manacapuru, Maués, Parintins, Humaitá, Itacoatiara, Tabatinga | I20: 3 | J20: 400
A21: SECRETARIA DE ESTADO ECONOMICO DO PIAUÍ – SDE - Teresina/PI | B21: 2026 | C21: Convênio nº 981837/2025 | D21: 72031.008918/2025-15 | E21: RP8 | F21: PI | G21: Teresina | H21: Teresina | I21: 20 | J21: 800
A22: SECRETARIA DE ESTADO ECONOMICO DO PIAUÍ – SDE - Parnaíba/PI | B22: 2026 | C22: Convênio nº 981838/2025 | D22: 72031.008917/2025-62 | E22: RP8 | F22: PI | G22: Teresina | H22: Parnaíba | I22: 20 | J22: 220
A23: SECRETARIA DE ESTADO ECONOMICO DO PIAUÍ – SDE - Luzilândia/PI | B23: 2026 | C23: Convênio nº 981840/2025 | D23: 72031.008914/2025-29 | E23: RP8 | F23: PI | G23: Teresina | H23: Luzilândia | I23: 20 | J23: 1620
A24: SECRETARIA DE ESTADO DE ASSISTENCIA SOCIAL, TRABALHO, EMPREGO E RENDA -SEASTER | B24: 2026 | C24: Convênio nº 981933/2025 | D24: 72031.007724/2025-94 | E24: RP8 | F24: PA | G24: Belém | H24: Ananindeua, Benevides, Marituba, Santa Bárbara do Pará | I24: 23 | J24: 500
A25: Secretaria de Estado de Turismo – SETUR - PA | B25: 2026 | C25: Convênio nº 982176/2025 | D25: 72031.007587/2025-98 | E25: RP8 | F25: PA | G25: Belém | H25: Belém | I25: 7 | J25: 1645
A26: ESTADO DO ACRE | B26: 2026 | C26: Convênio nº 984749/2025 | D26: 72031.009977/2025-01 | E26: RP8 | F26: AC | G26: Rio Branco | H26: Rio Branco, Cruzeiro do Sul, Tarauacá, Feijó, Epitaciolândia, Xapuri | I26: 11 | J26: 325
A27: SubTotal | I27: =SUM(I19:I26) -> 108 | J27: =SUM(J19:J26) -> 6410 | K27: =SUM(K19:K26) -> 646 | L27: =SUM(L19:L26) -> 311
A28: INSTITUTOS FEDERAIS E UNIVERSIDADES
A29: Instituto Federal de Educação, Ciência e Tecnologia do Maranhão - IFMA | B29: 2026 | C29: TED nº 988799/2025 | D29: 72031.009969/2025-56 | E29: RP8 | F29: MA | G29: Maranhão | H29: Buriti dos Lopes, Amarante, São Pedro do Piauí, Teresina, Cajueiro da Praia, Arraial, Cabaceiras do Piauí, Jardim do Mulato | I29: 25 | J29: 15640
A30: Instituto Federal de Educação, Ciência e Tecnologia Do Piauí – IFPI | B30: 2026 | C30: TED nº 987841/2025 | D30: 72031.009540/2025-69 | E30: RP8 | F30: PI | G30: Piauí | H30: Batalha, Luzilândia, Teresina, José de Freitas, Campo Maior, Piripiri, Luzilândia, Parnaíba, Luís Correia, Cajueiro da Praia, | I30: 4 | J30: 3200 | K30: 1795 | L30: 1642
A31: plataforma qualifica turismo (UFMA) | B31: 2025 | C31: TED nº 01/2022 | D31: 72031.002275/2021-64 | E31: RP2 | F31: MA | G31: Maranhão | H31: Nacional | I31: 2 | J31: 1004 | K31: 1004 | L31: 664
A32: Instituto Federal de Educação, Ciência e Tecnologia da Paraíba - IFPB | B32: 2025 | C32: TED nº 04/2020 | D32: 72031.011478/2020-61 | E32: 0100000000 | F32: PB | G32: Paraíba | H32: Nordeste | I32: 1 | J32: 377 | K32: 100 | L32: 69
A33: Instituto Federal de Educação, Ciência e Tecnologia Sul-riograndense (IFSul) | B33: 2025 | C33: TED nº 07/2020 | D33: 72031.013839/2020-11 | E33: RP2 | F33: RS | G33: Rio Grande do Sul | H33: Nacional | I33: 6 | J33: 6000 | K33: 7403 | L33: 2094
A34: Escola Nacional de Turismo (IFPA) | B34: 2025 | C34: TED nº 968127/2024 | D34: 72031.001167/2024-17 | E34: RP2 | F34: PA | G34: Belém | H34: Belém, Santarém, Vigia, Bragança, | I34: 140 | J34: 4040 | K34: 3479 | L34: 2737
A35: Universisade Federal Fluminense - UFF | B35: 2025 | C35: TED nº 01/2022 | D35: 72031.011644/2022-91 | E35: 0100000000 | F35: RJ | G35: Espírito Santo | H35: Sudeste | I35: 2 | J35: 45 | K35: 45 | L35: 45
A36: Instituto Federal de Educação, Ciência e Tecnologia do Tocantins -IFTO | B36: 2025 | C36: TED nº 004/2019 | D36: 72031.015203/2019-62 | E36: RP2 | F36: TO | G36: Palmas | H36: Nacional | I36: 2 | J36: 193 | K36: 193 | L36: 193
A37: plataforma qualifica turismo (UFMA) | B37: 2024 | C37: TED nº 01/2022 | D37: 72031.002275/2021-64 | E37: RP2 | F37: MA | G37: Maranhão | H37: Nacional | I37: 12 | J37: 1917 | K37: 1917 | L37: 1917
A38: Instituto Federal de Educação, Ciência e Tecnologia da Paraíba - IFPB | B38: 2024 | C38: TED nº 04/2020 | D38: 72031.011478/2020-61 | E38: 0100000000 | F38: PB | G38: Paraíba | H38: Nordeste | I38: 2 | J38: 919 | K38: 243 | L38: 160
A39: Instituto Federal de Educação, Ciência e Tecnologia Sul-riograndense (IFSul) | B39: 2024 | C39: TED nº 07/2020 | D39: 72031.013839/2020-11 | E39: RP2 | F39: RS | G39: Rio Grande do Sul | H39: Nacional | I39: 6 | J39: 8000 | K39: 3840 | L39: 1692
A40: Instituto Federal de Educação, Ciência e Tecnologia do Tocantins -IFTO | B40: 2024 | C40: TED nº 004/2019 | D40: 72031.015203/2019-62 | E40: RP2 | F40: TO | G40: Palmas | H40: Nacional | I40: 2 | J40: 528 | K40: 712 | L40: 409
A41: Universidade Federal do Tocantins - UFT | B41: 2024 | C41: TED nº 02/2020 | D41: 72031.011513/2020-41 | E41: 0100000000 | F41: TO | G41: Tocantins | H41: Norte e Centro-Oeste | I41: 4 | J41: 400 | K41: 615 | L41: 146
...

Sheet Planilha5

Sheet Planilha1
A1: 2023
A2: TED nº 006/2015 | B2: 72031.005057/2017-03
A3: TED nº 01/2022 | B3: 72031.002275/2021-64
A4: ACT nº 04/2022 | B4: 72031.013372/2022-63
A5: ACT nº 01/2022 | B5: 72031.013366/2022-14
A6: TED nº 02/2020 | B6: 72031.011513/2020-41
A7: TED nº 04/2020 | B7: 72031.011478/2020-61
A8: TED nº 004/2019 | B8: 72031.015203/2019-62
A9: TED nº 01/2022 | B9: 72031.011644/2022-91

Sheet Qualificados Total
A1: RELATÓRIO GERAL QUALIFICADOS 2023 a 2026 | AF1: 1
A2: Região | B2: Estado | C2: TOTAL GERAL 2023 | D2: TOTAL GERAL 2024 | E2: TOTAL GERAL 2025 | F2: TOTAL GERAL 2026 | G2: TOTAL GERAL DE 2023 A 2026 | AF2: 1
A3: Centro-Oeste | B3: Distrito Federal | C3: 78 | D3: 0 | E3: 14 | G3: =SUM(C3:F3) -> 92 | AF3: 1
A4: Centro-Oeste | B4: Goiás | C4: 39 | D4: 22 | E4: 0 | G4: =SUM(C4:F4) -> 61 | AF4: 1
A5: Centro-Oeste | B5: Mato Grosso | C5: 136 | D5: 0 | E5: 12 | G5: =SUM(C5:F5) -> 148 | AF5: 1
A6: Centro-Oeste | B6: Mato Grosso do Sul | C6: 87 | D6: 22 | E6: 25 | G6: =SUM(C6:F6) -> 134 | AF6: 1
B7: Subtotal Centro-Oeste | C7: =SUM(C3:C6) -> 340 | D7: =SUM(D3:D6) -> 44 | E7: =SUM(E3:E6) -> 51 | F7: =SUM(F3:F6) -> 0 | G7: =SUM(C7:F7) -> 435 | AF7: 1
A8: Nordeste | B8: Alagoas | C8: 102 | D8: 0 | E8: 10 | G8: =SUM(C8:F8) -> 112 | AF8: 1
A9: Nordeste | B9: Bahia | C9: 266 | D9: 0 | E9: 9 | G9: =SUM(C9:F9) -> 275 | AF9: 1
A10: Nordeste | B10: Ceará | C10: 78 | D10: 5 | E10: 0 | G10: =SUM(C10:F10) -> 83 | AF10: 1
A11: Nordeste | B11: Maranhão | C11: 73 | D11: 1962 | E11: 672 | G11: =SUM(C11:F11) -> 2707 | AF11: 1
A12: Nordeste | B12: Paraíba | C12: 76 | D12: 160 | E12: 69 | G12: =SUM(C12:F12) -> 305 | AF12: 1
A13: Nordeste | B13: Pernambuco | C13: 137 | D13: 0 | E13: 88 | G13: =SUM(C13:F13) -> 225 | AF13: 1
A14: Nordeste | B14: Piauí | C14: 34 | D14: 16 | E14: 15 | F14: 1642 | G14: =SUM(C14:F14) -> 1707 | AF14: 1
A15: Nordeste | B15: Rio Grande do Norte | C15: 56 | D15: 33 | E15: 31 | F15: 311 | G15: =SUM(C15:F15) -> 431 | AF15: 1
A16: Nordeste | B16: Sergipe | C16: 61 | D16: 0 | E16: 28 | G16: =SUM(C16:F16) -> 89 | AF16: 1
B17: Subtotal Nordeste | C17: =SUM(C8:C16) -> 883 | D17: =SUM(D8:D16) -> 2176 | E17: =SUM(E8:E16) -> 922 | F17: =SUM(F8:F16) -> 1953 | G17: =SUM(C17:F17) -> 5934 | AF17: 1
A18: Norte | B18: Acre | C18: 3 | D18: 0 | E18: 0 | G18: =SUM(C18:F18) -> 3 | AF18: 1
A19: Norte | B19: Amapá | C19: 2 | D19: 13 | E19: 15 | G19: =SUM(C19:F19) -> 30 | AF19: 1
A20: Norte | B20: Amazonas | C20: 61 | D20: 0 | E20: 76 | G20: =SUM(C20:F20) -> 137 | AF20: 1
A21: Norte | B21: Pará | C21: 166 | D21: 382 | E21: 2987 | G21: =SUM(C21:F21) -> 3535 | AF21: 1
A22: Norte | B22: Rondônia | C22: 74 | D22: 0 | E22: 13 | G22: =SUM(C22:F22) -> 87 | AF22: 1
A23: Norte | B23: Roraima | C23: 30 | D23: 0 | E23: 2 | G23: =SUM(C23:F23) -> 32 | AF23: 1
A24: Norte | B24: Tocantins | C24: 32 | D24: 555 | E24: 193 | G24: =SUM(C24:F24) -> 780 | AF24: 1
B25: Subtotal Norte | C25: =SUM(C18:C24) -> 368 | D25: =SUM(D18:D24) -> 950 | E25: =SUM(E18:E24) -> 3286 | F25: =SUM(F18:F24) -> 0 | G25: =SUM(C25:F25) -> 4604 | AF25: 1
A26: Sudeste | B26: Espírito Santo | C26: 277 | D26: 31 | E26: 25 | G26: =SUM(C26:F26) -> 333 | H26: 101 | I26: 176 | AF26: 1
A27: Sudeste | B27: Minas Gerais | C27: 199 | D27: 0 | E27: 57 | G27: =SUM(C27:F27) -> 256 | AF27: 1
A28: Sudeste | B28: Rio de Janeiro | C28: 642 | D28: 572 | E28: 196 | G28: =SUM(C28:F28) -> 1410 | AF28: 1
A29: Sudeste | B29: São Paulo | C29: 375 | D29: 6 | E29: 12 | G29: =SUM(C29:F29) -> 393 | AF29: 1
B30: Subtotal Sudeste | C30: =SUM(C26:C29) -> 1493 | D30: =SUM(D26:D29) -> 609 | E30: =SUM(E26:E29) -> 290 | F30: =SUM(F26:F29) -> 0 | G30: =SUM(C30:F30) -> 2392 | AF30: 1
A31: Sul | B31: Paraná | C31: 448 | D31: 353 | E31: 56 | G31: =SUM(C31:F31) -> 857 | AF31: 1
A32: Sul | B32: Rio Grande do Sul | C32: 173 | D32: 1692 | E32: 2262 | G32: =SUM(C32:F32) -> 4127 | H32: 402 | AF32: 1
A33: Sul | B33: Santa Catarina | C33: 181 | D33: 0 | E33: 47 | G33: =SUM(C33:F33) -> 228 | AF33: 1
B34: Subtotal Sul | C34: =SUM(C31:C33) -> 802 | D34: =SUM(D31:D33) -> 2045 | E34: =SUM(E31:E33) -> 2365 | F34: =SUM(F31:F33) -> 0 | G34: =SUM(C34:F34) -> 5212 | AF34: 1
A35: Estrangeiros | B35: Estrangeiros | C35: 10 | D35: 14 | E35: 10 | G35: =SUM(C35:F35) -> 34 | AF35: 1
B36: Total | C36: =C7+C17+C25+C30+C34+C35 -> 3896 | D36: =D7+D17+D25+D30+D34+D35 -> 5838 | E36: =E7+E17+E25+E30+E34+E35 -> 6924 | F36: =F7+F17+F25+F30+F34+F35 -> 1953 | G36: =SUM(C36:F36) -> 18611 | AF36: 1
AF37: 1

Sheet Planilha4
A3: Rótulos de Linha | B3: Soma de TOTAL GERAL 2025 | C3: Soma de TOTAL GERAL 2026
A4: Centro-Oeste | B4: 301
A5: Estrangeiros | B5: 10
A6: Nordeste | B6: 1373 | C6: 94
A7: Norte | B7: 4045
A8: Sudeste | B8: 2313
A9: Sul | B9: 1373
A10: Total Geral | B10: 9415 | C10: 94

Sheet Planilha3
A1: RELATÓRIO GERAL QUALIFICADOS 2023 a 2026
A2: Região | B2: Estado | C2: TOTAL GERAL 2023 | D2: TOTAL GERAL 2024 | E2: TOTAL GERAL 2025 | F2: TOTAL GERAL 2026 | G2: TOTAL GERAL DE 2023 A 2026
A3: Centro-Oeste | B3: Distrito Federal | C3: 79 | D3: 116 | E3: 96 | G3: =SUM(C3:F3) -> 291
A4: Centro-Oeste | B4: Goiás | C4: 41 | D4: 83 | E4: 85 | G4: =SUM(C4:F4) -> 209
A5: Centro-Oeste | B5: Mato Grosso | C5: 138 | D5: 41 | E5: 32 | G5: =SUM(C5:F5) -> 211
A6: Centro-Oeste | B6: Mato Grosso do Sul | C6: 88 | D6: 86 | E6: 88 | G6: =SUM(C6:F6) -> 262
A7: Nordeste | B7: Alagoas | C7: 105 | D7: 117 | E7: 151 | G7: =SUM(C7:F7) -> 373
A8: Nordeste | B8: Bahia | C8: 267 | D8: 252 | E8: 160 | G8: =SUM(C8:F8) -> 679
A9: Nordeste | B9: Ceará | C9: 79 | D9: 148 | E9: 178 | G9: =SUM(C9:F9) -> 405
A10: Nordeste | B10: Maranhão | C10: 74 | D10: 165 | E10: 91 | G10: =SUM(C10:F10) -> 330
A11: Nordeste | B11: Paraíba | C11: 77 | D11: 111 | E11: 122 | G11: =SUM(C11:F11) -> 310
A12: Nordeste | B12: Pernambuco | C12: 140 | D12: 203 | E12: 273 | G12: =SUM(C12:F12) -> 616
A13: Nordeste | B13: Piauí | C13: 34 | D13: 97 | E13: 87 | G13: =SUM(C13:F13) -> 218
A14: Nordeste | B14: Rio Grande do Norte | C14: 59 | D14: 225 | E14: 200 | F14: 94 | G14: =SUM(C14:F14) -> 578
A15: Nordeste | B15: Sergipe | C15: 64 | D15: 68 | E15: 111 | G15: =SUM(C15:F15) -> 243
A16: Norte | B16: Acre | C16: 3 | D16: 7 | E16: 8 | G16: =SUM(C16:F16) -> 18
A17: Norte | B17: Amapá | C17: 2 | D17: 36 | E17: 33 | G17: =SUM(C17:F17) -> 71
A18: Norte | B18: Amazonas | C18: 62 | D18: 127 | E18: 160 | G18: =SUM(C18:F18) -> 349
A19: Norte | B19: Pará | C19: 288 | D19: 868 | E19: 3723 | G19: =SUM(C19:F19) -> 4879
A20: Norte | B20: Rondônia | C20: 74 | D20: 56 | E20: 26 | G20: =SUM(C20:F20) -> 156
A21: Norte | B21: Roraima | C21: 31 | D21: 28 | E21: 24 | G21: =SUM(C21:F21) -> 83
A22: Norte | B22: Tocantins | C22: 33 | D22: 70 | E22: 71 | G22: =SUM(C22:F22) -> 174
A23: Sudeste | B23: Espírito Santo | C23: 179 | D23: 132 | E23: 87 | G23: =SUM(C23:F23) -> 398
A24: Sudeste | B24: Minas Gerais | C24: 191 | D24: 192 | E24: 346 | G24: =SUM(C24:F24) -> 729
A25: Sudeste | B25: Rio de Janeiro | C25: 552 | D25: 746 | E25: 879 | G25: =SUM(C25:F25) -> 2177
A26: Sudeste | B26: São Paulo | C26: 283 | D26: 906 | E26: 1001 | G26: =SUM(C26:F26) -> 2190
... A30: Estrangeiros | B30: Estrangeiros | C30: 10 | D30: 14 | E30: 10 | G30: =SUM(C30:F30) -> 34

Sheet Qualificados 2026
A1: RELATÓRIO GERAL QUALIFICADOS 2025
A2: Região | B2: Estado | C2: Setur - RN | D2: Instituto Federal - IFPI | K2: TOTAL GERAL
A3: Centro-Oeste | B3: Distrito Federal | K3: =SUM(C3:J3) -> 0
A4: Centro-Oeste | B4: Goiás | K4: =SUM(C4:J4) -> 0
A5: Centro-Oeste | B5: Mato Grosso | K5: =SUM(C5:J5) -> 0
A6: Centro-Oeste | B6: Mato Grosso do Sul | K6: =SUM(C6:J6) -> 0
B7: Subtotal Centro-Oeste | C7: =SUM(C3:C6) -> 0 | D7: =SUM(D3:D6) -> 0 | E7: =SUM(E3:E6) -> 0 | F7: =SUM(F3:F6) -> 0 | G7: =SUM(G3:G6) -> 0 | H7: =SUM(H3:H6) -> 0 | I7: =SUM(I3:I6) -> 0 | J7: =SUM(J3:J6) -> 0 | K7: =SUM(C7:J7) -> 0
A8: Nordeste | B8: Alagoas | K8: =SUM(C8:J8) -> 0
A9: Nordeste | B9: Bahia | K9: =SUM(C9:J9) -> 0
A10: Nordeste | B10: Ceará | K10: =SUM(C10:J10) -> 0
A11: Nordeste | B11: Maranhão | K11: =SUM(C11:J11) -> 0
A12: Nordeste | B12: Paraíba | K12: =SUM(C12:J12) -> 0
A13: Nordeste | B13: Pernambuco | K13: =SUM(C13:J13) -> 0
A14: Nordeste | B14: Piauí | D14: 1644 | K14: =SUM(C14:J14) -> 1644
A15: Nordeste | B15: Rio Grande do Norte | C15: 311 | K15: =SUM(C15:J15) -> 311
A16: Nordeste | B16: Sergipe | K16: =SUM(C16:J16) -> 0
B17: Subtotal Nordeste | C17: =SUM(C8:C16) -> 311 | D17: =SUM(D8:D16) -> 1644 | E17: =SUM(E8:E16) -> 0 | F17: =SUM(F8:F16) -> 0 | G17: =SUM(G8:G16) -> 0 | H17: =SUM(H8:H16) -> 0 | I17: =SUM(I8:I16) -> 0 | J17: =SUM(J8:J16) -> 0 | K17: =SUM(C17:J17) -> 1955
A18: Norte | B18: Acre | K18: =SUM(C18:J18) -> 0
A19: Norte | B19: Amapá | K19: =SUM(C19:J19) -> 0
A20: Norte | B20: Amazonas | K20: =SUM(C20:J20) -> 0
A21: Norte | B21: Pará | K21: =SUM(C21:J21) -> 0
A22: Norte | B22: Rondônia | K22: =SUM(C22:J22) -> 0
A23: Norte | B23: Roraima | K23: =SUM(C23:J23) -> 0
A24: Norte | B24: Tocantins | K24: =SUM(C24:J24) -> 0
B25: Subtotal Norte | C25: =SUM(C18:C24) -> 0 | D25: =SUM(D18:D24) -> 0 | E25: =SUM(E18:E24) -> 0 | F25: =SUM(F18:F24) -> 0 | G25: =SUM(G18:G24) -> 0 | H25: =SUM(H18:H24) -> 0 | I25: =SUM(I18:I24) -> 0 | J25: =SUM(J18:J24) -> 0 | K25: =SUM(C25:J25) -> 0
A26: Sudeste | B26: Espírito Santo | K26: =SUM(C26:J26) -> 0
A27: Sudeste | B27: Minas Gerais | K27: =SUM(C27:J27) -> 0
A28: Sudeste | B28: Rio de Janeiro | K28: =SUM(C28:J28) -> 0
A29: Sudeste | B29: São Paulo | K29: =SUM(C29:J29) -> 0
B30: Subtotal Sudeste | C30: =SUM(C26:C29) -> 0 | D30: =SUM(D26:D29) -> 0 | E30: =SUM(E26:E29) -> 0 | F30: =SUM(F26:F29) -> 0 | G30: =SUM(G26:G29) -> 0 | H30: =SUM(H26:H29) -> 0 | I30: =SUM(I26:I29) -> 0 | J30: =SUM(J26:J29) -> 0 | K30: =SUM(C30:J30) -> 0
A31: Sul | B31: Paraná | K31: =SUM(C31:J31) -> 0
A32: Sul | B32: Rio Grande do Sul | K32: =SUM(C32:J32) -> 0
A33: Sul | B33: Santa Catarina | K33: =SUM(C33:J33) -> 0
B34: Subtotal Sul | C34: =SUM(C31:C33) -> 0 | D34: =SUM(D31:D33) -> 0 | E34: =SUM(E31:E33) -> 0 | F34: =SUM(F31:F33) -> 0 | G34: =SUM(G31:G33) -> 0 | H34: =SUM(H31:H33) -> 0 | I34: =SUM(I31:I33) -> 0 | J34: 0 | K34: =SUM(C34:J34) -> 0
A35: Estrangeiros | B35: Estrangeiros | K35: =SUM(C35:J35) -> 0
B36: Total | C36: =SUM(C7,C17,C25,C30,C34,C35) -> 311 | D36: =SUM(D7,D17,D25,D30,D34,D35) -> 1644 | E36: =SUM(E7,E17,E25,E30,E34,E35) -> 0 | F36: =SUM(F7,F17,F25,F30,F34,F35) -> 0 | G36: =SUM(G7,G17,G25,G30,G34,G35) -> 0 | H36: =SUM(H7,H17,H25,H30,H34,H35) -> 0 | I36: =SUM(I7,I17,I25,I30,I34,I35) -> 0 | J36: =SUM(J7,J17,J25,J30,J34,J35) -> 0 | K36: =SUM(C36:J36) -> 1955

Sheet Qualificados 2025
A1: MINISTÉRIO DO TURISMO Secretaria Nacional de Política de Turismo Departamento de Qualidade, sustentabilidade e Ações Clímaticas no Turismo Coordenação-Geral de Qualificação no Turismo Atualizado em 12/01/2026
A2: RELATÓRIO GERAL QUALIFICADOS 2025
A3: Região | B3: Estado | C3: Curso de Gestor de Turismo - CGT (Plataforma PEA) | D3: plataforma qualifica turismo | E3: Escola Nacional do Turismo IFPA | F3: Instituto Federal de Educação, Ciência e Tecnologia da Paraíba - IFPB​ | G3: Instituto Federal de Educação, Ciência e Tecnologia Sul-riograndense (IFSul) | H3: Instituto Federal de Educação, Ciência e Tecnologia do Tocantins (IFTO) | I3: Acordo de Cooperação Técnica Mtur/Sesc/Senac n°002/2023 | J3: Universidade Federal Fluminense - Sudeste - UFF | K3: TOTAL GERAL
A4: Centro-Oeste | B4: Distrito Federal | C4: 0 | D4: 14 | E4: 0 | F4: 0 | G4: 35 | H4: 33 | I4: 14 | J4: 0 | K4: =SUM(D4:J4) -> 96
A5: Centro-Oeste | B5: Goiás | C5: 0 | D5: 10 | E5: 0 | F5: 0 | G5: 43 | H5: 32 | I5: 0 | J5: 0 | K5: =SUM(D5:J5) -> 85
A6: Centro-Oeste | B6: Mato Grosso | C6: 2 | D6: 5 | E6: 0 | F6: 0 | G6: 14 | H6: 13 | I6: 0 | J6: 0 | K6: =SUM(D6:J6) -> 32
A7: Centro-Oeste | B7: Mato Grosso do Sul | C7: 1 | D7: 7 | E7: 0 | F7: 0 | G7: 29 | H7: 34 | I7: 18 | J7: 0 | K7: =SUM(D7:J7) -> 88
B8: Subtotal Centro-Oeste | C8: =SUM(C4:C7) -> 3 | D8: =SUM(D4:D7) -> 36 | E8: =SUM(E4:E7) -> 0 | F8: =SUM(F4:F7) -> 0 | G8: =SUM(G4:G7) -> 121 | H8: =SUM(H4:H7) -> 112 | I8: =SUM(I4:I7) -> 32 | J8: =SUM(J4:J7) -> 0 | K8: =SUM(C8:J8) -> 304
A9: Nordeste | B9: Alagoas | C9: 0 | D9: 12 | E9: 0 | F9: 9 | G9: 76 | H9: 44 | I9: 10 | J9: 0 | K9: =SUM(D9:J9) -> 151
A10: Nordeste | B10: Bahia | C10: 0 | D10: 29 | E10: 0 | F10: 4 | G10: 60 | H10: 68 | I10: 9 | J10: 0 | K10: =SUM(D10:J10) -> 170
A11: Nordeste | B11: Ceará | C11: 0 | D11: 33 | E11: 0 | F11: 10 | G11: 79 | H11: 55 | I11: 1 | J11: 0 | K11: =SUM(D11:J11) -> 178
A12: Nordeste | B12: Maranhão | C12: 1 | D12: 16 | E12: 0 | F12: 3 | G12: 33 | H12: 32 | I12: 9 | J12: 0 | K12: =SUM(D12:J12) -> 93
A13: Nordeste | B13: Paraíba | C13: 0 | D13: 25 | E13: 0 | F13: 12 | G13: 44 | H13: 41 | I13: 0 | J13: 0 | K13: =SUM(D13:J13) -> 122
A14: Nordeste | B14: Pernambuco | C14: 0 | D14: 27 | E14: 0 | F14: 14 | G14: 74 | H14: 70 | I14: 88 | J14: 0 | K14: =SUM(D14:J14) -> 273
A15: Nordeste | B15: Piauí | C15: 0 | D15: 8 | E15: 0 | F15: 4 | G15: 26 | H15: 34 | I15: 15 | J15: 0 | K15: =SUM(D15:J15) -> 87
A16: Nordeste | B16: Rio Grande do Norte | C16: 0 | D16: 8 | E16: 0 | F16: 7 | G16: 89 | H16: 65 | I16: 31 | J16: 0 | K16: =SUM(D16:J16) -> 200
A17: Nordeste | B17: Sergipe | C17: 0 | D17: 6 | E17: 0 | F17: 6 | G17: 19 | H17: 52 | I17: 28 | J17: 0 | K17: =SUM(D17:J17) -> 111
B18: Subtotal Nordeste | C18: =SUM(C9:C17) -> 1 | D18: =SUM(D9:D17) -> 164 | E18: =SUM(E9:E17) -> 0 | F18: =SUM(F9:F17) -> 69 | G18: =SUM(G9:G17) -> 500 | H18: =SUM(H9:H17) -> 461 | I18: =SUM(I9:I17) -> 191 | J18: =SUM(J9:J17) -> 0 | K18: =SUM(C18:J18) -> 1386
A19: Norte | B19: Acre | C19: 0 | D19: 4 | E19: 0 | F19: 0 | G19: 1 | H19: 3 | I19: 0 | J19: 0 | K19: =SUM(D19:J19) -> 8
A20: Norte | B20: Amapá | C20: 0 | D20: 1 | E20: 0 | F20: 0 | G20: 9 | H20: 8 | I20: 15 | J20: 0 | K20: =SUM(D20:J20) -> 33
A21: Norte | B21: Amazonas | C21: 0 | D21: 3 | E21: 0 | F21: 0 | G21: 52 | H21: 29 | I21: 76 | J21: 0 | K21: =SUM(D21:J21) -> 160
A22: Norte | B22: Pará | C22: 2 | D22: 19 | E22: 3109 | F22: 0 | G22: 54 | H22: 79 | I22: 316 | J22: 0 | K22: =SUM(D22:J22) -> 3577
A23: Norte | B23: Rondônia | C23: 0 | D23: 0 | E23: 0 | F23: 0 | G23: 11 | H23: 2 | I23: 13 | J23: 0 | K23: =SUM(D23:J23) -> 26
A24: Norte | B24: Roraima | C24: 0 | D24: 3 | E24: 0 | F24: 0 | G24: 19 | H24: 0 | I24: 2 | J24: 0 | K24: =SUM(D24:J24) -> 24
A25: Norte | B25: Tocantins | C25: 0 | D25: 7 | E25: 0 | F25: 0 | G25: 9 | H25: 55 | I25: 0 | J25: 0 | K25: =SUM(D25:J25) -> 71
B26: Subtotal Norte | C26: =SUM(C19:C25) -> 2 | D26: =SUM(D19:D25) -> 37 | E26: =SUM(E19:E25) -> 3109 | F26: =SUM(F19:F25) -> 0 | G26: =SUM(G19:G25) -> 155 | H26: =SUM(H19:H25) -> 176 | I26: =SUM(I19:I25) -> 422 | J26: =SUM(J19:J25) -> 0 | K26: =SUM(C26:J26) -> 3901
A27: Sudeste | B27: Espírito Santo | C27: 0 | D27: 12 | E27: 0 | F27: 0 | G27: 24 | H27: 23 | I27: 27 | J27: 1 | K27: =SUM(D27:J27) -> 87
A28: Sudeste | B28: Minas Gerais | C28: 0 | D28: 50 | E28: 0 | F28: 0 | G28: 156 | H28: 118 | I28: 27 | J28: 5 | K28: =SUM(D28:J28) -> 356
A29: Sudeste | B29: Rio de Janeiro | C29: 1 | D29: 97 | E29: 0 | F29: 0 | G29: 187 | H29: 459 | I29: 116 | J29: 20 | K29: =SUM(D29:J29) -> 879
A30: Sudeste | B30: São Paulo | C30: 1 | D30: 154 | E30: 0 | F30: 0 | G30: 203 | H30: 611 | I30: 14 | J30: 19 | K30: =SUM(D30:J30) -> 1001
B31: Subtotal Sudeste | C31: =SUM(C27:C30) -> 2 | D31: =SUM(D27:D30) -> 313 | E31: =SUM(E27:E30) -> 0 | F31: =SUM(F27:F30) -> 0 | G31: =SUM(G27:G30) -> 570 | H31: =SUM(H27:H30) -> 1211 | I31: =SUM(I27:I30) -> 184 | J31: =SUM(J27:J30) -> 45 | K31: =SUM(C31:J31) -> 2325
A32: Sul | B32: Paraná | C32: 0 | D32: 25 | E32: 0 | F32: 0 | G32: 57 | H32: 71 | I32: 78 | J32: 0 | K32: =SUM(D32:J32) -> 231
A33: Sul | B33: Rio Grande do Sul | C33: 0 | D33: 37 | E33: 0 | F33: 0 | G33: 655 | H33: 95 | I33: 168 | J33: 0 | K33: =SUM(D33:J33) -> 955
A34: Sul | B34: Santa Catarina | C34: 0 | D34: 34 | E34: 0 | F34: 0 | G34: 46 | H34: 58 | I34: 47 | J34: 0 | K34: =SUM(D34:J34) -> 185
B35: Subtotal Sul | C35: =SUM(C32:C34) -> 0 | D35: =SUM(D32:D34) -> 96 | E35: =SUM(E32:E34) -> 0 | F35: =SUM(F32:F34) -> 0 | G35: =SUM(G32:G34) -> 758 | H35: =SUM(H32:H34) -> 224 | I35: =SUM(I32:I34) -> 293 | J35: 0 | K35: =SUM(C35:J35) -> 1371
A36: Estrangeiros | B36: Estrangeiros | C36: 0 | D36: 10 | E36: 0 | F36: 0 | G36: 0 | H36: 0 | I36: 0 | J36: 0 | K36: =SUM(C36:J36) -> 10
B37: Total | C37: =SUM(C8,C18,C26,C31,C35,C36) -> 8 | D37: =SUM(D8,D18,D26,D31,D35,D36) -> 656 | E37: =SUM(E8,E18,E26,E31,E35,E36) -> 3109 | F37: =SUM(F8,F18,F26,F31,F35,F36) -> 69 | G37: =SUM(G8,G18,G26,G31,G35,G36) -> 2104 | H37: =SUM(H8,H18,H26,H31,H35,H36) -> 2184 | I37: =SUM(I8,I18,I26,I31,I35,I36) -> 1122 | J37: =SUM(J8,J18,J26,J31,J35,J36) -> 45 | K37: =SUM(K8,K18,K26,K31,K35,K36) -> 9297

Sheet Qualificados 2024
A1: RELATÓRIO GERAL QUALIFICADOS 2024
A2: Região | B2: Estado | C2: Atendimento ao Turista - Brasil Braços Abertos - BBA | D2: Curso de Gestor de Turismo - CGT | E2: Universidade Federal do Tocantins - UFT | F2: Instituto Federal de Educação, Ciência e Tecnologia da Paraíba - IFPB​ | G2: Universidade Federal Fluminense Tocantins - UFF | H2: Instituto Federal de Educação, Ciência e Tecnologia Sul-riograndense (IFSul) | I2: Instituto Federal de Tocantins - IFTO (Inglês e Espanhol) | J2: Senac-PR | K2: plataforma qualifica turismo | L2: Escola Nacional IFPA | M2: ACT/SESC/SENAC | N2: TOTAL GERAL | P2: TOTAL GERAL 2024
A3: Centro-Oeste | B3: Distrito Federal | C3: 0 | D3: 0 | E3: 20 | F3: 0 | G3: 0 | H3: 37 | I3: 10 | J3: 0 | K3: 49 | L3: 0 | M3: 0 | N3: =SUM(C3:M3) -> 116 | P3: 116
A4: Centro-Oeste | B4: Goiás | C4: 0 | D4: 1 | E4: 12 | F4: 0 | G4: 0 | H4: 16 | I4: 9 | J4: 15 | K4: 30 | L4: 0 | M4: 0 | N4: =SUM(C4:M4) -> 83 | P4: 83
A5: Centro-Oeste | B5: Mato Grosso | C5: 0 | D5: 1 | E5: 6 | F5: 0 | G5: 0 | H5: 9 | I5: 3 | J5: 0 | K5: 22 | L5: 0 | M5: 0 | N5: =SUM(C5:M5) -> 41 | P5: 41
A6: Centro-Oeste | B6: Mato Grosso do Sul | C6: 0 | D6: 0 | E6: 10 | F6: 0 | G6: 0 | H6: 8 | I6: 5 | J6: 0 | K6: 41 | L6: 0 | M6: 22 | N6: =SUM(C6:M6) -> 86 | P6: 86
B7: Subtotal Centro-Oeste | C7: =SUM(C3:C6) -> 0 | D7: =SUM(D3:D6) -> 2 | E7: =SUM(E3:E6) -> 48 | F7: =SUM(F3:F6) -> 0 | G7: 0 | H7: =SUM(H3:H6) -> 70 | I7: =SUM(I3:I6) -> 27 | J7: =SUM(J3:J6) -> 15 | K7: =SUM(K3:K6) -> 142 | L7: 0 | M7: =SUM(M3:M6) -> 22 | N7: =SUM(C7:M7) -> 326 | P7: =SUM(P3:P6) -> 326
A8: Nordeste | B8: Alagoas | C8: 1 | D8: 2 | E8: 0 | F8: 19 | G8: 0 | H8: 29 | I8: 7 | J8: 0 | K8: 59 | L8: 0 | M8: 0 | N8: =SUM(C8:M8) -> 117 | P8: 117
